Workbook

Sheet BP
A1: LUILU RESSOURCES SAS 鲁依鲁资源简易股份有限公司
A3: 167 AV.BUKAMA Q.MUTOSHI | K3: Tel:+243 843613879
A4: C/MANIKA, KOLWEZI | K4: E-mail:xieboyang@hkexcellen.com
A5: Province du Lualaba, Democratic Republic of Congo | C5: BULLETIN DE PESAGE/WEIGHTING SHEET:LU-EX Conc.-2026-9-11-049
A7: Client: SINGAPORE EXCELLEN PTE.LTD/SINGAPORE | I7: AGENCE EN DOUANE: | K7: CONNEX
A8: Destination：Singapore | I8: License NO.： | K8: DEC1798930-4F06-EB
A9: Product: COPPER CONCENTRATE | I9: Loading Point: | K9: LUILU PLANT
A11: NO. | B11: LOT NO. | C11: HORSE NO. | D11: TRAILER 1 | E11: TRAILER 2 | F11: CONTAINER NO | G11: DRIVER NAME | H11: PASSPORT | I11: TRANSPORTER | J11: BORDER | K11: PKGS | L11: G.W(T) | M11: N.W(T)
A12: 1 | B12: EX202609-0506 | C12: T641EKD | D12: T560EKD | E12: NA | F12: NA | G12: OMARY HAMISI | H12: AB02109553 | I12: VAN MO COMPANY LIMITED | J12: Dar es Salaam | K12: =COUNTA('1装'!B19:B40) -> 22 | L12: =M12+K12*0.003 -> 30.719 | M12: ='1装'!C42/1000 -> 30.653
A13: 2 | B13: EX202609-0507 | C13: T963ERN | D13: T918ERX | E13: NA | F13: NA | G13: IDDI IBRAHIMU | H13: TAE326185 | I13: VAN MO COMPANY LIMITED | J13: Dar es Salaam | K13: =COUNTA('2装'!B19:B44) -> 26 | L13: =M13+K13*0.003 -> 30.65 | M13: ='2装'!C46/1000 -> 30.572
A14: 3 | B14: EX202609-0508 | C14: T688ERQ | D14: T281ERY | E14: NA | F14: NA | G14: JOHN ANDREW | H14: TAE678691 | I14: VAN MO COMPANY LIMITED | J14: Dar es Salaam | K14: =COUNTA('3装'!B19:B41) -> 23 | L14: =M14+K14*0.003 -> 30.65 | M14: ='3装'!C43/1000 -> 30.581
A15: 4 | B15: EX202609-0509 | C15: T615EFE | D15: T881EFH | E15: NA | F15: NA | G15: ALLY KITOSI | H15: AB02088841 | I15: IMPERIAL ROAD HAULAGE LTD | J15: Dar es Salaam | K15: =COUNTA('4装'!B19:B39) -> 21 | L15: =M15+K15*0.003 -> 30.65 | M15: ='4装'!C41/1000 -> 30.587
A16: 5 | B16: EX202609-0510 | C16: T284EEY | D16: T634EEZ | E16: NA | F16: NA | G16: NICHOLAUS LISAKAFU | H16: TAE644895 | I16: IMPERIAL ROAD HAULAGE LTD | J16: Dar es Salaam | K16: =COUNTA('5装'!B19:B38) -> 20 | L16: =M16+K16*0.003 -> 29.596 | M16: ='5装'!C40/1000 -> 29.536
A17: 6 | B17: EX202609-0511 | C17: T994EKU | D17: T236EKS | E17: NA | F17: NA | G17: MSANGI SULEMANI | H17: TAE953270 | I17: IMPERIAL ROAD HAULAGE LTD | J17: Dar es Salaam | K17: =COUNTA('6装'!B19:B40) -> 22 | L17: =M17+K17*0.003 -> 31.693 | M17: ='6装'!C42/1000 -> 31.627
A18: 7 | B18: EX202609-0512 | C18: FWH557L | D18: FPC417L | E18: FPC421L | F18: NA | G18: GRESTEN MWEEMBA | H18: ZN904984 | I18: GREENDOOR GROUP (PTY) LTD | J18: DURBAN | K18: =COUNTA('7装'!B19:B42) -> 24 | L18: =M18+K18*0.003 -> 33.655 | M18: ='7装'!C44/1000 -> 33.583
A19: 8 | B19: EX202609-0513 | C19: FPV477L | D19: FMG170L | E19: FMG167L | F19: NA | G19: BRIGHT FUNDA | H19: ZP106451 | I19: GREENDOOR GROUP (PTY) LTD | J19: DURBAN | K19: =COUNTA('8装'!B19:B42) -> 24 | L19: =M19+K19*0.003 -> 33.648 | M19: ='8装'!C44/1000 -> 33.576
A20: 9 | B20: EX202609-0514 | C20: T574ECB | D20: T185BDN | E20: T232DTC | F20: NA | G20: MASHIKU JEREMIAH | H20: AB02100763 | I20: C.STEINWEG BRIDGE (PTY) LTD | J20: Dar es Salaam | K20: =COUNTA('9装'!B19:B42) -> 24 | L20: =M20+K20*0.003 -> 33.833 | M20: ='9装'!C44/1000 -> 33.761
A21: 10 | B21: EX202609-0515 | C21: T174DYN | D21: T345BSA | E21: T254EKH | F21: NA | G21: MIKAEHAEL CHARLES | H21: TAE652658 | I21: C.STEINWEG BRIDGE (PTY) LTD | J21: Dar es Salaam | K21: =COUNTA('10装'!B19:B43) -> 25 | L21: =M21+K21*0.003 -> 34.625 | M21: ='10装'!C45/1000 -> 34.55
A22: 11 | B22: EX202609-0516 | C22: T593EAL | D22: T147BGL | E22: T726EGF | F22: NA | G22: HASSAN NGUZO | H22: TAE800128 | I22: C.STEINWEG BRIDGE (PTY) LTD | J22: Dar es Salaam | K22: =COUNTA('11装'!B19:B43) -> 25 | L22: =M22+K22*0.003 -> 34.678 | M22: ='11装'!C45/1000 -> 34.603
A23: 12 | B23: EX202609-0517 | C23: T546ELH | D23: T993DAU | E23: T228DTC | F23: NA | G23: MICHAEL | H23: TAE779136 | I23: C.STEINWEG BRIDGE (PTY) LTD | J23: Dar es Salaam | K23: =COUNTA('12装'!B19:B42) -> 24 | L23: =M23+K23*0.003 -> 33.815 | M23: ='12装'!C44/1000 -> 33.743
A24: 13 | B24: EX202609-0518 | C24: T407DNB | D24: T480BRX | E24: T414EMV | F24: NA | G24: ALEX PETER | H24: AB02100906 | I24: C.STEINWEG BRIDGE (PTY) LTD | J24: Dar es Salaam | K24: =COUNTA('13装'!B19:B42) -> 24 | L24: =M24+K24*0.003 -> 33.666 | M24: ='13装'!C44/1000 -> 33.594
A25: 14 | B25: EX202609-0519 | C25: T265ECC | D25: T983EBY | E25: T713EGF | F25: NA | G25: JAPHET FIKENI KITUMA | H25: TAE679080 | I25: C.STEINWEG BRIDGE (PTY) LTD | J25: Dar es Salaam | K25: =COUNTA('14装'!B19:B43) -> 25 | L25: =M25+K25*0.003 -> 33.939 | M25: ='14装'!C45/1000 -> 33.864
A26: 15 | B26: EX202609-0520 | C26: T485EAL | D26: T331DEN | E26: T710EGF | F26: NA | G26: EDIGA YORAM | H26: AB02093890 | I26: C.STEINWEG BRIDGE (PTY) LTD | J26: Dar es Salaam | K26: =COUNTA('15装'!B19:B41) -> 23 | L26: =M26+K26*0.003 -> 33.893 | M26: ='15装'!C43/1000 -> 33.824
A27: 16 | B27: EX202609-0521 | C27: T177EBK | D27: T796BMY | E27: T973EHX | F27: NA | G27: ISSA MANYANGA | H27: TAE842876 | I27: C.STEINWEG BRIDGE (PTY) LTD | J27: Dar es Salaam | K27: =COUNTA('16装'!B19:B42) -> 24 | L27: =M27+K27*0.003 -> 34.074 | M27: ='16装'!C44/1000 -> 34.002
A28: 17 | B28: EX202609-0522 | C28: T952DUM | D28: T919ASZ | E28: NA | F28: NA | G28: MIKA KISUNGWE | H28: TAE650086 | I28: C.STEINWEG BRIDGE (PTY) LTD | J28: Dar es Salaam | K28: =COUNTA('17装'!B19:B40) -> 22 | L28: =M28+K28*0.003 -> 29.65 | M28: ='17装'!C42/1000 -> 29.584
A29: 18 | B29: EX202609-0523 | C29: T502DMJ | D29: T440CFG | E29: T364ELY | F29: NA | G29: SHARIFU JUMANNE | H29: TAE869967 | I29: C.STEINWEG BRIDGE (PTY) LTD | J29: Dar es Salaam | K29: =COUNTA('18装'!B19:B41) -> 23 | L29: =M29+K29*0.003 -> 33.73 | M29: ='18装'!C43/1000 -> 33.661
A30: 19 | B30: EX202609-0524 | C30: T540ECN | D30: T827ENG | E30: NA | F30: NA | G30: MUSTAFER AMIR | H30: AB02106113 | I30: IMPERIAL ROAD HAULAGE LTD | J30: Dar es Salaam | K30: =COUNTA('19装'!B19:B41) -> 23 | L30: =M30+K30*0.003 -> 32.548 | M30: ='19装'!C43/1000 -> 32.479
A31: 20 | B31: EX202609-0525 | C31: T699DRY | D31: T699DRY | E31: T207DSK | F31: NA | G31: CHARLES LUCAS MTENGULE | H31: TAE690209 | I31: OVERLAND INTERNATIONAL AG | J31: Dar es Salaam | K31: =COUNTA('20装'!B19:B42) -> 24 | L31: =M31+K31*0.003 -> 33.754 | M31: ='20装'!C44/1000 -> 33.682
A32: 21 | B32: EX202609-0526 | C32: T341EPL | D32: T731EPJ | E32: NA | F32: NA | G32: SALEHE HEMEDI | H32: TAE791546 | I32: VAN MO COMPANY LIMITED | J32: Dar es Salaam | K32: =COUNTA('21装'!B19:B40) -> 22 | L32: =M32+K32*0.003 -> 30.65 | M32: ='21装'!C42/1000 -> 30.584
A33: 22 | B33: EX202609-0527 | C33: T626ECB | D33: T557BBE | E33: T236DTC | F33: NA | G33: SALUM MUMBA | H33: TAE527007 | I33: C.STEINWEG BRIDGE (PTY) LTD | J33: Dar es Salaam | K33: =COUNTA('22装'!B19:B43) -> 25 | L33: =M33+K33*0.003 -> 33.827 | M33: ='22装'!C45/1000 -> 33.752
A34: 23 | B34: EX202609-0528 | C34: T222DFL | D34: T596CBD | E34: T429EMV | F34: NA | G34: MUSTAFA OMARY | H34: AB02103761 | I34: C.STEINWEG BRIDGE (PTY) LTD | J34: Dar es Salaam | K34: =COUNTA('23装'!B19:B42) -> 24 | L34: =M34+K34*0.003 -> 34.762 | M34: ='23装'!C44/1000 -> 34.69
A35: 24 | B35: EX202609-0529 | C35: T602DYY | D35: T494BRX | E35: T415EPH | F35: NA | G35: IDDI JUMA | H35: TAE854999 | I35: C.STEINWEG BRIDGE (PTY) LTD | J35: Dar es Salaam | K35: =COUNTA('24装'!B19:B41) -> 23 | L35: =M35+K35*0.003 -> 34.339 | M35: ='24装'!C43/1000 -> 34.27
A36: 25 | B36: EX202609-0530 | C36: T605EGH | D36: T314ECC | E36: T980EHQ | F36: NA | G36: RAMADHAN RUME | H36: TAE499949 | I36: C.STEINWEG BRIDGE (PTY) LTD | J36: Dar es Salaam | K36: =COUNTA('25装'!B19:B43) -> 25 | L36: =M36+K36*0.003 -> 34.727 | M36: ='25装'!C45/1000 -> 34.652
A37: 26 | B37: EX202609-0531 | C37: T412EEG | D37: T826EFK | E37: NA | F37: NA | G37: HASSAN OMAR | H37: TAE180869 | I37: IMPERIAL ROAD HAULAGE LTD | J37: Dar es Salaam | K37: =COUNTA('26装'!B19:B39) -> 21 | L37: =M37+K37*0.003 -> 30.648 | M37: ='26装'!C41/1000 -> 30.585
I38: TOTAL | K38: =SUM(K12:K37) -> 608 | L38: =SUM(L12:L37) -> 852.419 | M38: =SUM(M12:M37) -> 850.595
B41: SIGNATURE: | I41: KOLWEZI, | M41: 46276

Sheet 1装
A1: LUILU RESSOURCES SAS 鲁依鲁资源简易股份有限公司
A3: 167 AV.BUKAMA Q.MUTOSHI | D3: Tel:+243843613879
A4: C/MANIKA, KOLWEZI | D4: E-mail:xieboyang@hkexcellen.com
A5: Province du Lualaba, Democratic Republic of Congo
A6: LISTE DE COLISAGE
A7: DESCRIPTION: | B7: CONCENTRÉ DE CUIVRE | C7: N° DE LISTE DE COLISAGE : | D7: =BP!B12 -> EX202609-0506
A8: DATE: | B8: =BP!M41 -> 46276
A9: DÉTAILS DU CAMION
A10: CHEVAL: | B10: =IF(BP!C12="","",BP!C12) -> T641EKD
A11: CHARIOT-REMORQUE 1 : | B11: =IF(BP!D12="","",BP!D12) -> T560EKD | C11: CHARIOT-REMORQUE 2: | D11: =IF(BP!E12="","",BP!E12) -> NA
A12: CONDUCTEUR: | B12: =IF(BP!G12="","",BP!G12) -> OMARY HAMISI | C12: PASSPORT: | D12: =IF(BP!H12="","",BP!H12) -> AB02109553
A13: LIEU DE CHARGEMENT : L’ USINE DE LUILU
A14: TRANSPORTEUR: | B14: =IF(BP!I12="","",BP!I12) -> VAN MO COMPANY LIMITED
A15: TRANSIT: | B15: /
A16: BORDER: | B16: =IF(BP!J12="","",BP!J12) -> Dar es Salaam
A17: AGENT: | B17: =BP!K7 -> CONNEX
A18: NO. | B18: BAG NO. | C18: NET WEIGHT(KG) | D18: SEAL NO.
A19: 1 | B19: LU-CC26090500301 | C19: 1333 | D19: DC15001
A20: 2 | B20: LU-CC26090500325 | C20: 1402 | D20: DC15025
A21: 3 | B21: LU-CC26090500253 | C21: 1381 | D21: DC15053
A22: 4 | B22: LU-CC26090500254 | C22: 1386 | D22: DC15054
A23: 5 | B23: LU-CC26090500219 | C23: 1400 | D23: DC01919
A24: 6 | B24: LU-CC26090500331 | C24: 1438 | D24: DC15031
A25: 7 | B25: LU-CC26090500344 | C25: 1448 | D25: DC01744
A26: 8 | B26: LU-CC26090500309 | C26: 1359 | D26: DC15009
A27: 9 | B27: LU-CC26090500276 | C27: 1389 | D27: DC15076
A28: 10 | B28: LU-CC26090500320 | C28: 1444 | D28: DC15020
A29: 11 | B29: LU-CC26090400208 | C29: 1385 | D29: DC01908
A30: 12 | B30: LU-CC26090500287 | C30: 1379 | D30: DC15087
... A40: 22 | B40: LU-CC26090500278 | C40: 1430 | D40: DC15078
A42: TOTAL： | C42: =SUM(C19:C40) -> 30653
A45: BENEFICIARY
A46: LUILU RESSOURCES SAS
A47: Conseil chaleureux : veuillez vérifier le numéro/poids/lots/pièces du camion avant de signer
A48: DRIVER: | C48: SUPPLY:
A49: TRANSPORT AGENT: | C49: SECURITY:

Sheet 2装
A1: LUILU RESSOURCES SAS 鲁依鲁资源简易股份有限公司
A3: 167 AV.BUKAMA Q.MUTOSHI | D3: Tel:+243843613879
A4: C/MANIKA, KOLWEZI | D4: E-mail:xieboyang@hkexcellen.com
A5: Province du Lualaba, Democratic Republic of Congo
A6: LISTE DE COLISAGE
A7: DESCRIPTION: | B7: CONCENTRÉ DE CUIVRE | C7: N° DE LISTE DE COLISAGE : | D7: =BP!B13 -> EX202609-0507
A8: DATE: | B8: =BP!M41 -> 46276
A9: DÉTAILS DU CAMION
A10: CHEVAL: | B10: =IF(BP!C13="","",BP!C13) -> T963ERN
A11: CHARIOT-REMORQUE 1 : | B11: =IF(BP!D13="","",BP!D13) -> T918ERX | C11: CHARIOT-REMORQUE 2: | D11: =IF(BP!E13="","",BP!E13) -> NA
A12: CONDUCTEUR: | B12: =IF(BP!G13="","",BP!G13) -> IDDI IBRAHIMU | C12: PASSPORT: | D12: =IF(BP!H13="","",BP!H13) -> TAE326185
A13: LIEU DE CHARGEMENT : L’ USINE DE LUILU
A14: TRANSPORTEUR: | B14: =IF(BP!I13="","",BP!I13) -> VAN MO COMPANY LIMITED
A15: TRANSIT: | B15: /
A16: BORDER: | B16: =IF(BP!J13="","",BP!J13) -> Dar es Salaam
A17: AGENT: | B17: =BP!K7 -> CONNEX
A18: NO. | B18: BAG NO. | C18: NET WEIGHT(KG) | D18: SEAL NO.
A19: 1 | B19: LU-CC25123031 | C19: 1390 | D19: 111096
A20: 2 | B20: LU-CC25122860 | C20: 1354 | D20: 111402
A21: 3 | B21: LU-CC25122871 | C21: 1348 | D21: 111413
A22: 4 | B22: LU-CC25123185 | C22: 1008 | D22: 111285
A23: 5 | B23: LU-CC25123160 | C23: 1181 | D23: 111260
A24: 6 | B24: LU-CC25123179 | C24: 1019 | D24: 111279
A25: 7 | B25: LU-CC25123170 | C25: 1072 | D25: 111270
A26: 8 | B26: LU-CC25123178 | C26: 1060 | D26: 111278
A27: 9 | B27: LU-CC26010213 | C27: 1023 | D27: 111613
A28: 10 | B28: LU-CC26010237 | C28: 1159 | D28: 111637
A29: 11 | B29: LU-CC25123169 | C29: 1042 | D29: 111269
A30: 12 | B30: LU-CC25123127 | C30: 1177 | D30: 111227
... A44: 26 | B44: LU-CC26072802 | C44: 1254 | D44: 113602
A46: TOTAL： | C46: =SUM(C19:C44) -> 30572
A49: BENEFICIARY
A50: LUILU RESSOURCES SAS
A51: Conseil chaleureux : veuillez vérifier le numéro/poids/lots/pièces du camion avant de signer
A52: DRIVER: | C52: SUPPLY:
A53: TRANSPORT AGENT: | C53: SECURITY:

Sheet 3装
A1: LUILU RESSOURCES SAS 鲁依鲁资源简易股份有限公司
A3: 167 AV.BUKAMA Q.MUTOSHI | D3: Tel:+243843613879
A4: C/MANIKA, KOLWEZI | D4: E-mail:xieboyang@hkexcellen.com
A5: Province du Lualaba, Democratic Republic of Congo
A6: LISTE DE COLISAGE
A7: DESCRIPTION: | B7: CONCENTRÉ DE CUIVRE | C7: N° DE LISTE DE COLISAGE : | D7: =BP!B14 -> EX202609-0508
A8: DATE: | B8: =BP!M41 -> 46276
A9: DÉTAILS DU CAMION
A10: CHEVAL: | B10: =IF(BP!C14="","",BP!C14) -> T688ERQ
A11: CHARIOT-REMORQUE 1 : | B11: =IF(BP!D14="","",BP!D14) -> T281ERY | C11: CHARIOT-REMORQUE 2: | D11: =IF(BP!E14="","",BP!E14) -> NA
A12: CONDUCTEUR: | B12: =IF(BP!G14="","",BP!G14) -> JOHN ANDREW | C12: PASSPORT: | D12: =IF(BP!H14="","",BP!H14) -> TAE678691
A13: LIEU DE CHARGEMENT : L’ USINE DE LUILU
A14: TRANSPORTEUR: | B14: =IF(BP!I14="","",BP!I14) -> VAN MO COMPANY LIMITED
A15: TRANSIT: | B15: /
A16: BORDER: | B16: =IF(BP!J14="","",BP!J14) -> Dar es Salaam
A17: AGENT: | B17: =BP!K7 -> CONNEX
A18: NO. | B18: BAG NO. | C18: NET WEIGHT(KG) | D18: SEAL NO.
A19: 1 | B19: LU-CC260727224 | C19: 1336 | D19: 114595
A20: 2 | B20: LU-CC26072836 | C20: 1371 | D20: 113636
A21: 3 | B21: LU-CC26072857 | C21: 1356 | D21: 113657
A22: 4 | B22: LU-CC26072897 | C22: 1319 | D22: 113697
A23: 5 | B23: LU-CC26072844 | C23: 1436 | D23: 113644
A24: 6 | B24: LU-CC26072843 | C24: 1404 | D24: 113643
A25: 7 | B25: LU-CC26072865 | C25: 1409 | D25: 113665
A26: 8 | B26: LU-CC26072832 | C26: 1380 | D26: 113632
A27: 9 | B27: LU-CC26072864 | C27: 1374 | D27: 113664
A28: 10 | B28: LU-CC26072833 | C28: 1344 | D28: 113633
A29: 11 | B29: LU-CC26072866 | C29: 1354 | D29: 113666
A30: 12 | B30: LU-CC26072834 | C30: 1381 | D30: 113634
... A41: 23 | B41: LU-CC26072886 | C41: 1227 | D41: 113686
A43: TOTAL： | C43: =SUM(C19:C41) -> 30581
A46: BENEFICIARY
A47: LUILU RESSOURCES SAS
A48: Conseil chaleureux : veuillez vérifier le numéro/poids/lots/pièces du camion avant de signer
A49: DRIVER: | C49: SUPPLY:
A50: TRANSPORT AGENT: | C50: SECURITY:

Sheet 4装
A1: LUILU RESSOURCES SAS 鲁依鲁资源简易股份有限公司
A3: 167 AV.BUKAMA Q.MUTOSHI | D3: Tel:+243843613879
A4: C/MANIKA, KOLWEZI | D4: E-mail:xieboyang@hkexcellen.com
A5: Province du Lualaba, Democratic Republic of Congo
A6: LISTE DE COLISAGE
A7: DESCRIPTION: | B7: CONCENTRÉ DE CUIVRE | C7: N° DE LISTE DE COLISAGE : | D7: =BP!B15 -> EX202609-0509
A8: DATE: | B8: =BP!M41 -> 46276
A9: DÉTAILS DU CAMION
A10: CHEVAL: | B10: =IF(BP!C15="","",BP!C15) -> T615EFE
A11: CHARIOT-REMORQUE 1 : | B11: =IF(BP!D15="","",BP!D15) -> T881EFH | C11: CHARIOT-REMORQUE 2: | D11: =IF(BP!E15="","",BP!E15) -> NA
A12: CONDUCTEUR: | B12: =IF(BP!G15="","",BP!G15) -> ALLY KITOSI | C12: PASSPORT: | D12: =IF(BP!H15="","",BP!H15) -> AB02088841
A13: LIEU DE CHARGEMENT : L’ USINE DE LUILU
A14: TRANSPORTEUR: | B14: =IF(BP!I15="","",BP!I15) -> IMPERIAL ROAD HAULAGE LTD
A15: TRANSIT: | B15: /
A16: BORDER: | B16: =IF(BP!J15="","",BP!J15) -> Dar es Salaam
A17: AGENT: | B17: =BP!K7 -> CONNEX
A18: NO. | B18: BAG NO. | C18: NET WEIGHT(KG) | D18: SEAL NO.
A19: 1 | B19: LU-CC26090300081 | C19: 1548 | D19: DC14481
A20: 2 | B20: LU-CC26090700942 | C20: 1661 | D20: DC14642
A21: 3 | B21: LU-CC26090300059 | C21: 1398 | D21: DC14459
A22: 4 | B22: LU-CC26090300073 | C22: 1450 | D22: DC14473
A23: 5 | B23: LU-CC26090300089 | C23: 1421 | D23: DC14489
A24: 6 | B24: LU-CC26090300099 | C24: 1422 | D24: DC14499
A25: 7 | B25: LU-CC26090300066 | C25: 1581 | D25: DC14466
A26: 8 | B26: LU-CC26090300052 | C26: 1426 | D26: DC14452
A27: 9 | B27: LU-CC26090300074 | C27: 1556 | D27: DC14474
A28: 10 | B28: LU-CC26090300082 | C28: 1524 | D28: DC14482
A29: 11 | B29: LU-CC26090300090 | C29: 1353 | D29: DC14490
A30: 12 | B30: LU-CC26090300067 | C30: 1463 | D30: DC14467
... A39: 21 | B39: LU-CC26090300042 | C39: 1415 | D39: DC14442
A41: TOTAL： | C41: =SUM(C19:C39) -> 30587
A44: BENEFICIARY
A45: LUILU RESSOURCES SAS
A46: Conseil chaleureux : veuillez vérifier le numéro/poids/lots/pièces du camion avant de signer
A47: DRIVER: | C47: SUPPLY:
A48: TRANSPORT AGENT: | C48: SECURITY:

Sheet 5装
A1: LUILU RESSOURCES SAS 鲁依鲁资源简易股份有限公司
A3: 167 AV.BUKAMA Q.MUTOSHI | D3: Tel:+243843613879
A4: C/MANIKA, KOLWEZI | D4: E-mail:xieboyang@hkexcellen.com
A5: Province du Lualaba, Democratic Republic of Congo
A6: LISTE DE COLISAGE
A7: DESCRIPTION: | B7: CONCENTRÉ DE CUIVRE | C7: N° DE LISTE DE COLISAGE : | D7: =BP!B16 -> EX202609-0510
A8: DATE: | B8: =BP!M41 -> 46276
A9: DÉTAILS DU CAMION
A10: CHEVAL: | B10: =IF(BP!C16="","",BP!C16) -> T284EEY
A11: CHARIOT-REMORQUE 1 : | B11: =IF(BP!D16="","",BP!D16) -> T634EEZ | C11: CHARIOT-REMORQUE 2: | D11: =IF(BP!E16="","",BP!E16) -> NA
A12: CONDUCTEUR: | B12: =IF(BP!G16="","",BP!G16) -> NICHOLAUS LISAKAFU | C12: PASSPORT: | D12: =IF(BP!H16="","",BP!H16) -> TAE644895
A13: LIEU DE CHARGEMENT : L’ USINE DE LUILU
A14: TRANSPORTEUR: | B14: =IF(BP!I16="","",BP!I16) -> IMPERIAL ROAD HAULAGE LTD
A15: TRANSIT: | B15: /
A16: BORDER: | B16: =IF(BP!J16="","",BP!J16) -> Dar es Salaam
A17: AGENT: | B17: =BP!K7 -> CONNEX
A18: NO. | B18: BAG NO. | C18: NET WEIGHT(KG) | D18: SEAL NO.
A19: 1 | B19: LU-CC26090300108 | C19: 1390 | D19: DC14408
A20: 2 | B20: LU-CC26090300094 | C20: 1422 | D20: DC14494
A21: 3 | B21: LU-CC26090300085 | C21: 1496 | D21: DC14485
A22: 4 | B22: LU-CC26090300056 | C22: 1584 | D22: DC14456
A23: 5 | B23: LU-CC26090300070 | C23: 1545 | D23: DC14470
A24: 6 | B24: LU-CC26090300078 | C24: 1423 | D24: DC14478
A25: 7 | B25: LU-CC26090300086 | C25: 1451 | D25: DC14486
A26: 8 | B26: LU-CC26090300071 | C26: 1540 | D26: DC14471
A27: 9 | B27: LU-CC26090300079 | C27: 1539 | D27: DC14479
A28: 10 | B28: LU-CC26090300095 | C28: 1535 | D28: DC14495
A29: 11 | B29: LU-CC26090300048 | C29: 1459 | D29: DC14448
A30: 12 | B30: LU-CC26090300049 | C30: 1528 | D30: DC14449
... A38: 20 | B38: LU-CC26090300050 | C38: 1439 | D38: DC02023
A40: TOTAL： | C40: =SUM(C19:C38) -> 29536
A44: LUILU RESSOURCES SAS
A45: Conseil chaleureux : veuillez vérifier le numéro/poids/lots/pièces du camion avant de signer
A46: DRIVER: | C46: SUPPLY:
A47: TRANSPORT AGENT: | C47: SECURITY:

Sheet 6装
A1: LUILU RESSOURCES SAS 鲁依鲁资源简易股份有限公司
A3: 167 AV.BUKAMA Q.MUTOSHI | D3: Tel:+243843613879
A4: C/MANIKA, KOLWEZI | D4: E-mail:xieboyang@hkexcellen.com
A5: Province du Lualaba, Democratic Republic of Congo
A6: LISTE DE COLISAGE
A7: DESCRIPTION: | B7: CONCENTRÉ DE CUIVRE | C7: N° DE LISTE DE COLISAGE : | D7: =BP!B17 -> EX202609-0511
A8: DATE: | B8: =BP!M41 -> 46276
A9: DÉTAILS DU CAMION
A10: CHEVAL: | B10: =IF(BP!C17="","",BP!C17) -> T994EKU
A11: CHARIOT-REMORQUE 1 : | B11: =IF(BP!D17="","",BP!D17) -> T236EKS | C11: CHARIOT-REMORQUE 2: | D11: =IF(BP!E17="","",BP!E17) -> NA
A12: CONDUCTEUR: | B12: =IF(BP!G17="","",BP!G17) -> MSANGI SULEMANI | C12: PASSPORT: | D12: =IF(BP!H17="","",BP!H17) -> TAE953270
A13: LIEU DE CHARGEMENT : L’ USINE DE LUILU
A14: TRANSPORTEUR: | B14: =IF(BP!I17="","",BP!I17) -> IMPERIAL ROAD HAULAGE LTD
A15: TRANSIT: | B15: /
A16: BORDER: | B16: =IF(BP!J17="","",BP!J17) -> Dar es Salaam
A17: AGENT: | B17: =BP!K7 -> CONNEX
A18: NO. | B18: BAG NO. | C18: NET WEIGHT(KG) | D18: SEAL NO.
A19: 1 | B19: LU-CC26090400159 | C19: 1383 | D19: DC01959
A20: 2 | B20: LU-CC26090400128 | C20: 1449 | D20: DC14428
A21: 3 | B21: LU-CC26090400149 | C21: 1375 | D21: DC01949
A22: 4 | B22: LU-CC26090400141 | C22: 1420 | D22: DC01941
A23: 5 | B23: LU-CC26090400140 | C23: 1368 | D23: DC01940
A24: 6 | B24: LU-CC26090400151 | C24: 1304 | D24: DC01951
A25: 7 | B25: LU-CC26090400123 | C25: 1405 | D25: DC14423
A26: 8 | B26: LU-CC26090400127 | C26: 1418 | D26: DC14427
A27: 9 | B27: LU-CC26090400148 | C27: 1393 | D27: DC01948
A28: 10 | B28: LU-CC26090400124 | C28: 1331 | D28: DC14424
A29: 11 | B29: LU-CC26090300091 | C29: 1385 | D29: DC14491
A30: 12 | B30: LU-CC26090300061 | C30: 1503 | D30: DC14461
... A40: 22 | B40: LU-CC26090300103 | C40: 1481 | D40: DC14403
A42: TOTAL： | C42: =SUM(C19:C40) -> 31627
A45: BENEFICIARY
A46: LUILU RESSOURCES SAS
A47: Conseil chaleureux : veuillez vérifier le numéro/poids/lots/pièces du camion avant de signer
A48: DRIVER: | C48: SUPPLY:
A49: TRANSPORT AGENT: | C49: SECURITY:

Sheet 7装
A1: LUILU RESSOURCES SAS 鲁依鲁资源简易股份有限公司
A3: 167 AV.BUKAMA Q.MUTOSHI | D3: Tel:+243843613879
A4: C/MANIKA, KOLWEZI | D4: E-mail:xieboyang@hkexcellen.com
A5: Province du Lualaba, Democratic Republic of Congo
A6: LISTE DE COLISAGE
A7: DESCRIPTION: | B7: CONCENTRÉ DE CUIVRE | C7: N° DE LISTE DE COLISAGE : | D7: =BP!B18 -> EX202609-0512
A8: DATE: | B8: =BP!M41 -> 46276
A9: DÉTAILS DU CAMION
A10: CHEVAL: | B10: =IF(BP!C18="","",BP!C18) -> FWH557L
A11: CHARIOT-REMORQUE 1 : | B11: =IF(BP!D18="","",BP!D18) -> FPC417L | C11: CHARIOT-REMORQUE 2: | D11: =IF(BP!E18="","",BP!E18) -> FPC421L
A12: CONDUCTEUR: | B12: =IF(BP!G18="","",BP!G18) -> GRESTEN MWEEMBA | C12: PASSPORT: | D12: =IF(BP!H18="","",BP!H18) -> ZN904984
A13: LIEU DE CHARGEMENT : L’ USINE DE LUILU
A14: TRANSPORTEUR: | B14: =IF(BP!I18="","",BP!I18) -> GREENDOOR GROUP (PTY) LTD
A15: TRANSIT: | B15: /
A16: BORDER: | B16: =IF(BP!J18="","",BP!J18) -> DURBAN
A17: AGENT: | B17: =BP!K7 -> CONNEX
A18: NO. | B18: BAG NO. | C18: NET WEIGHT(KG) | D18: SEAL NO.
A19: 1 | B19: LU-CC26090400163 | C19: 1385 | D19: DC01963
A20: 2 | B20: LU-CC26090400119 | C20: 1473 | D20: DC14419
A21: 3 | B21: LU-CC26090400144 | C21: 1329 | D21: DC01944
A22: 4 | B22: LU-CC26090400132 | C22: 1403 | D22: DC14432
A23: 5 | B23: LU-CC26090400156 | C23: 1362 | D23: DC01956
A24: 6 | B24: LU-CC26090400136 | C24: 1410 | D24: DC14436
A25: 7 | B25: LU-CC26090400155 | C25: 1420 | D25: DC01955
A26: 8 | B26: LU-CC26090400131 | C26: 1330 | D26: DC14431
A27: 9 | B27: LU-CC26090400145 | C27: 1378 | D27: DC01945
A28: 10 | B28: LU-CC26090400137 | C28: 1351 | D28: DC14437
A29: 11 | B29: LU-CC26090400130 | C29: 1361 | D29: DC14430
A30: 12 | B30: LU-CC26090400147 | C30: 1407 | D30: DC01947
... A42: 24 | B42: LU-CC26090300101 | C42: 1456 | D42: DC14401
A44: TOTAL： | C44: =SUM(C19:C42) -> 33583
A47: BENEFICIARY
A48: LUILU RESSOURCES SAS
A49: Conseil chaleureux : veuillez vérifier le numéro/poids/lots/pièces du camion avant de signer
A50: DRIVER: | C50: SUPPLY:
A51: TRANSPORT AGENT: | C51: SECURITY:

Sheet 8装
A1: LUILU RESSOURCES SAS 鲁依鲁资源简易股份有限公司
A3: 167 AV.BUKAMA Q.MUTOSHI | D3: Tel:+243843613879
A4: C/MANIKA, KOLWEZI | D4: E-mail:xieboyang@hkexcellen.com
A5: Province du Lualaba, Democratic Republic of Congo
A6: LISTE DE COLISAGE
A7: DESCRIPTION: | B7: CONCENTRÉ DE CUIVRE | C7: N° DE LISTE DE COLISAGE : | D7: =BP!B19 -> EX202609-0513
A8: DATE: | B8: =BP!M41 -> 46276
A9: DÉTAILS DU CAMION
A10: CHEVAL: | B10: =IF(BP!C19="","",BP!C19) -> FPV477L
A11: CHARIOT-REMORQUE 1 : | B11: =IF(BP!D19="","",BP!D19) -> FMG170L | C11: CHARIOT-REMORQUE 2: | D11: =IF(BP!E19="","",BP!E19) -> FMG167L
A12: CONDUCTEUR: | B12: =IF(BP!G19="","",BP!G19) -> BRIGHT FUNDA | C12: PASSPORT: | D12: =IF(BP!H19="","",BP!H19) -> ZP106451
A13: LIEU DE CHARGEMENT : L’ USINE DE LUILU
A14: TRANSPORTEUR: | B14: =IF(BP!I19="","",BP!I19) -> GREENDOOR GROUP (PTY) LTD
A15: TRANSIT: | B15: /
A16: BORDER: | B16: =IF(BP!J19="","",BP!J19) -> DURBAN
A17: AGENT: | B17: =BP!K7 -> CONNEX
A18: NO. | B18: BAG NO. | C18: NET WEIGHT(KG) | D18: SEAL NO.
A19: 1 | B19: LU-CC26090400186 | C19: 1326 | D19: DC01986
A20: 2 | B20: LU-CC26090400187 | C20: 1451 | D20: DC01987
A21: 3 | B21: LU-CC26090400174 | C21: 1356 | D21: DC01974
A22: 4 | B22: LU-CC26090400175 | C22: 1368 | D22: DC01975
A23: 5 | B23: LU-CC26090400210 | C23: 1357 | D23: DC01910
A24: 6 | B24: LU-CC26090400199 | C24: 1296 | D24: DC01999
A25: 7 | B25: LU-CC26090400211 | C25: 1436 | D25: DC01911
A26: 8 | B26: LU-CC26090400176 | C26: 1451 | D26: DC01976
A27: 9 | B27: LU-CC26090400200 | C27: 1333 | D27: DC02000
A28: 10 | B28: LU-CC26090400189 | C28: 1301 | D28: DC01989
A29: 11 | B29: LU-CC26090400177 | C29: 1409 | D29: DC01977
A30: 12 | B30: LU-CC26090400134 | C30: 1250 | D30: DC14434
... A42: 24 | B42: LU-CC26090300046 | C42: 1571 | D42: DC14446
A44: TOTAL： | C44: =SUM(C19:C42) -> 33576
A47: BENEFICIARY
A48: LUILU RESSOURCES SAS
A49: Conseil chaleureux : veuillez vérifier le numéro/poids/lots/pièces du camion avant de signer
A50: DRIVER: | C50: SUPPLY:
A51: TRANSPORT AGENT: | C51: SECURITY:

Sheet 9装
A1: LUILU RESSOURCES SAS 鲁依鲁资源简易股份有限公司
A3: 167 AV.BUKAMA Q.MUTOSHI | D3: Tel:+243843613879
A4: C/MANIKA, KOLWEZI | D4: E-mail:xieboyang@hkexcellen.com
A5: Province du Lualaba, Democratic Republic of Congo
A6: LISTE DE COLISAGE
A7: DESCRIPTION: | B7: CONCENTRÉ DE CUIVRE | C7: N° DE LISTE DE COLISAGE : | D7: =BP!B20 -> EX202609-0514
A8: DATE: | B8: =BP!M41 -> 46276
A9: DÉTAILS DU CAMION
A10: CHEVAL: | B10: =IF(BP!C20="","",BP!C20) -> T574ECB
A11: CHARIOT-REMORQUE 1 : | B11: =IF(BP!D20="","",BP!D20) -> T185BDN | C11: CHARIOT-REMORQUE 2: | D11: =IF(BP!E20="","",BP!E20) -> T232DTC
A12: CONDUCTEUR: | B12: =IF(BP!G20="","",BP!G20) -> MASHIKU JEREMIAH | C12: PASSPORT: | D12: =IF(BP!H20="","",BP!H20) -> AB02100763
A13: LIEU DE CHARGEMENT : L’ USINE DE LUILU
A14: TRANSPORTEUR: | B14: =IF(BP!I20="","",BP!I20) -> C.STEINWEG BRIDGE (PTY) LTD
A15: TRANSIT: | B15: /
A16: BORDER: | B16: =IF(BP!J20="","",BP!J20) -> Dar es Salaam
A17: AGENT: | B17: =BP!K7 -> CONNEX
A18: NO. | B18: BAG NO. | C18: NET WEIGHT(KG) | D18: SEAL NO.
A19: 1 | B19: LU-CC26090500412 | C19: 1356 | D19: DC01712
A20: 2 | B20: LU-CC26090700746 | C20: 1437 | D20: DC01446
A21: 3 | B21: LU-CC26090700709 | C21: 1537 | D21: DC01409
A22: 4 | B22: LU-CC26090700697 | C22: 1435 | D22: DC14997
A23: 5 | B23: LU-CC26090600501 | C23: 1424 | D23: DC15301
A24: 6 | B24: LU-CC26090700700 | C24: 1327 | D24: DC02044
A25: 7 | B25: LU-CC26090600456 | C25: 1447 | D25: DC15356
A26: 8 | B26: LU-CC26090700710 | C26: 1434 | D26: DC01410
A27: 9 | B27: LU-CC26090700696 | C27: 1290 | D27: DC14996
A28: 10 | B28: LU-CC26090600468 | C28: 1390 | D28: DC15368
A29: 11 | B29: LU-CC26090700698 | C29: 1385 | D29: DC14998
A30: 12 | B30: LU-CC26090600440 | C30: 1396 | D30: DC15340
... A42: 24 | B42: LU-CC26090600543 | C42: 1462 | D42: DC19943
A44: TOTAL： | C44: =SUM(C19:C42) -> 33761
A47: BENEFICIARY
A48: LUILU RESSOURCES SAS
A49: Conseil chaleureux : veuillez vérifier le numéro/poids/lots/pièces du camion avant de signer
A50: DRIVER: | C50: SUPPLY:
A51: TRANSPORT AGENT: | C51: SECURITY:

Sheet 10装
A1: LUILU RESSOURCES SAS 鲁依鲁资源简易股份有限公司
A3: 167 AV.BUKAMA Q.MUTOSHI | D3: Tel:+243843613879
A4: C/MANIKA, KOLWEZI | D4: E-mail:xieboyang@hkexcellen.com
A5: Province du Lualaba, Democratic Republic of Congo
A6: LISTE DE COLISAGE
A7: DESCRIPTION: | B7: CONCENTRÉ DE CUIVRE | C7: N° DE LISTE DE COLISAGE : | D7: =BP!B21 -> EX202609-0515
A8: DATE: | B8: =BP!M41 -> 46276
A9: DÉTAILS DU CAMION
A10: CHEVAL: | B10: =IF(BP!C21="","",BP!C21) -> T174DYN
A11: CHARIOT-REMORQUE 1 : | B11: =IF(BP!D21="","",BP!D21) -> T345BSA | C11: CHARIOT-REMORQUE 2: | D11: =IF(BP!E21="","",BP!E21) -> T254EKH
A12: CONDUCTEUR: | B12: =IF(BP!G21="","",BP!G21) -> MIKAEHAEL CHARLES | C12: PASSPORT: | D12: =IF(BP!H21="","",BP!H21) -> TAE652658
A13: LIEU DE CHARGEMENT : L’ USINE DE LUILU
A14: TRANSPORTEUR: | B14: =IF(BP!I21="","",BP!I21) -> C.STEINWEG BRIDGE (PTY) LTD
A15: TRANSIT: | B15: /
A16: BORDER: | B16: =IF(BP!J21="","",BP!J21) -> Dar es Salaam
A17: AGENT: | B17: =BP!K7 -> CONNEX
A18: NO. | B18: BAG NO. | C18: NET WEIGHT(KG) | D18: SEAL NO.
A19: 1 | B19: LU-CC26090500388 | C19: 1336 | D19: DC01788
A20: 2 | B20: LU-CC26090500377 | C20: 1318 | D20: DC01777
A21: 3 | B21: LU-CC26090500408 | C21: 1304 | D21: DC01708
A22: 4 | B22: LU-CC26090600464 | C22: 1420 | D22: DC15364
A23: 5 | B23: LU-CC26090600451 | C23: 1314 | D23: DC15351
A24: 6 | B24: LU-CC26090600452 | C24: 1436 | D24: DC15352
A25: 7 | B25: LU-CC26090500417 | C25: 1361 | D25: DC01717
A26: 8 | B26: LU-CC26090600435 | C26: 1313 | D26: DC02067
A27: 9 | B27: LU-CC26090600453 | C27: 1463 | D27: DC15353
A28: 10 | B28: LU-CC26090600465 | C28: 1210 | D28: DC15365
A29: 11 | B29: LU-CC26090600434 | C29: 1452 | D29: DC01734
A30: 12 | B30: LU-CC26090600455 | C30: 1341 | D30: DC15355
... A43: 25 | B43: LU-CC26090600498 | C43: 1522 | D43: DC15398
A45: TOTAL： | C45: =SUM(C19:C43) -> 34550
A48: BENEFICIARY
A49: LUILU RESSOURCES SAS
A50: Conseil chaleureux : veuillez vérifier le numéro/poids/lots/pièces du camion avant de signer
A51: DRIVER: | C51: SUPPLY:
A52: TRANSPORT AGENT: | C52: SECURITY:

Sheet 11装
A1: LUILU RESSOURCES SAS 鲁依鲁资源简易股份有限公司
A3: 167 AV.BUKAMA Q.MUTOSHI | D3: Tel:+243843613879
A4: C/MANIKA, KOLWEZI | D4: E-mail:xieboyang@hkexcellen.com
A5: Province du Lualaba, Democratic Republic of Congo
A6: LISTE DE COLISAGE
A7: DESCRIPTION: | B7: CONCENTRÉ DE CUIVRE | C7: N° DE LISTE DE COLISAGE : | D7: =BP!B22 -> EX202609-0516
A8: DATE: | B8: =BP!M41 -> 46276
A9: DÉTAILS DU CAMION
A10: CHEVAL: | B10: =IF(BP!C22="","",BP!C22) -> T593EAL
A11: CHARIOT-REMORQUE 1 : | B11: =IF(BP!D22="","",BP!D22) -> T147BGL | C11: CHARIOT-REMORQUE 2: | D11: =IF(BP!E22="","",BP!E22) -> T726EGF
A12: CONDUCTEUR: | B12: =IF(BP!G22="","",BP!G22) -> HASSAN NGUZO | C12: PASSPORT: | D12: =IF(BP!H22="","",BP!H22) -> TAE800128
A13: LIEU DE CHARGEMENT : L’ USINE DE LUILU
A14: TRANSPORTEUR: | B14: =IF(BP!I22="","",BP!I22) -> C.STEINWEG BRIDGE (PTY) LTD
A15: TRANSIT: | B15: /
A16: BORDER: | B16: =IF(BP!J22="","",BP!J22) -> Dar es Salaam
A17: AGENT: | B17: =BP!K7 -> CONNEX
A18: NO. | B18: BAG NO. | C18: NET WEIGHT(KG) | D18: SEAL NO.
A19: 1 | B19: LU-CC26090500398 | C19: 1387 | D19: DC01798
A20: 2 | B20: LU-CC26090500379 | C20: 1418 | D20: DC01779
A21: 3 | B21: LU-CC26090500371 | C21: 1379 | D21: DC01771
A22: 4 | B22: LU-CC26090500354 | C22: 1380 | D22: DC01754
A23: 5 | B23: LU-CC26090500368 | C23: 1377 | D23: DC01768
A24: 6 | B24: LU-CC26090500389 | C24: 1324 | D24: DC01789
A25: 7 | B25: LU-CC26090500375 | C25: 1400 | D25: DC01775
A26: 8 | B26: LU-CC26090500355 | C26: 1249 | D26: DC01755
A27: 9 | B27: LU-CC26090500409 | C27: 1496 | D27: DC01709
A28: 10 | B28: LU-CC26090500376 | C28: 1206 | D28: DC01776
A29: 11 | B29: LU-CC26090500356 | C29: 1341 | D29: DC01756
A30: 12 | B30: LU-CC26090500380 | C30: 1328 | D30: DC01780
... A43: 25 | B43: LU-CC26090600432 | C43: 1543 | D43: DC01732
A45: TOTAL： | C45: =SUM(C19:C43) -> 34603
A48: BENEFICIARY
A49: LUILU RESSOURCES SAS
A50: Conseil chaleureux : veuillez vérifier le numéro/poids/lots/pièces du camion avant de signer
A51: DRIVER: | C51: SUPPLY:
A52: TRANSPORT AGENT: | C52: SECURITY:

Sheet 12装
A1: LUILU RESSOURCES SAS 鲁依鲁资源简易股份有限公司
A3: 167 AV.BUKAMA Q.MUTOSHI | D3: Tel:+243843613879
A4: C/MANIKA, KOLWEZI | D4: E-mail:xieboyang@hkexcellen.com
A5: Province du Lualaba, Democratic Republic of Congo
A6: LISTE DE COLISAGE
A7: DESCRIPTION: | B7: CONCENTRÉ DE CUIVRE | C7: N° DE LISTE DE COLISAGE : | D7: =BP!B23 -> EX202609-0517
A8: DATE: | B8: =BP!M41 -> 46276
A9: DÉTAILS DU CAMION
A10: CHEVAL: | B10: =IF(BP!C23="","",BP!C23) -> T546ELH
A11: CHARIOT-REMORQUE 1 : | B11: =IF(BP!D23="","",BP!D23) -> T993DAU | C11: CHARIOT-REMORQUE 2: | D11: =IF(BP!E23="","",BP!E23) -> T228DTC
A12: CONDUCTEUR: | B12: =IF(BP!G23="","",BP!G23) -> MICHAEL | C12: PASSPORT: | D12: =IF(BP!H23="","",BP!H23) -> TAE779136
A13: LIEU DE CHARGEMENT : L’ USINE DE LUILU
A14: TRANSPORTEUR: | B14: =IF(BP!I23="","",BP!I23) -> C.STEINWEG BRIDGE (PTY) LTD
A15: TRANSIT: | B15: /
A16: BORDER: | B16: =IF(BP!J23="","",BP!J23) -> Dar es Salaam
A17: AGENT: | B17: =BP!K7 -> CONNEX
A18: NO. | B18: BAG NO. | C18: NET WEIGHT(KG) | D18: SEAL NO.
A19: 1 | B19: LU-CC26090600499 | C19: 1560 | D19: DC15399
A20: 2 | B20: LU-CC26090500382 | C20: 1323 | D20: DC01782
A21: 3 | B21: LU-CC26090500402 | C21: 1343 | D21: DC01702
A22: 4 | B22: LU-CC26090700721 | C22: 1421 | D22: DC01421
A23: 5 | B23: LU-CC26090500360 | C23: 1447 | D23: DC01760
A24: 6 | B24: LU-CC26090500383 | C24: 1396 | D24: DC01783
A25: 7 | B25: LU-CC26090600428 | C25: 1395 | D25: DC01728
A26: 8 | B26: LU-CC26090600487 | C26: 1345 | D26: DC15387
A27: 9 | B27: LU-CC26090600431 | C27: 1494 | D27: DC01731
A28: 10 | B28: LU-CC26090600477 | C28: 1339 | D28: DC15377
A29: 11 | B29: LU-CC26090600491 | C29: 1424 | D29: DC15391
A30: 12 | B30: LU-CC26090600459 | C30: 1397 | D30: DC15359
... A42: 24 | B42: LU-CC26090600530 | C42: 1408 | D42: DC15330
A44: TOTAL： | C44: =SUM(C19:C42) -> 33743
A47: BENEFICIARY
A48: LUILU RESSOURCES SAS
A49: Conseil chaleureux : veuillez vérifier le numéro/poids/lots/pièces du camion avant de signer
A50: DRIVER: | C50: SUPPLY:
A51: TRANSPORT AGENT: | C51: SECURITY:

Sheet 13装
A1: LUILU RESSOURCES SAS 鲁依鲁资源简易股份有限公司
A3: 167 AV.BUKAMA Q.MUTOSHI | D3: Tel:+243843613879
A4: C/MANIKA, KOLWEZI | D4: E-mail:xieboyang@hkexcellen.com
A5: Province du Lualaba, Democratic Republic of Congo
A6: LISTE DE COLISAGE
A7: DESCRIPTION: | B7: CONCENTRÉ DE CUIVRE | C7: N° DE LISTE DE COLISAGE : | D7: =BP!B24 -> EX202609-0518
A8: DATE: | B8: =BP!M41 -> 46276
A9: DÉTAILS DU CAMION
A10: CHEVAL: | B10: =IF(BP!C24="","",BP!C24) -> T407DNB
A11: CHARIOT-REMORQUE 1 : | B11: =IF(BP!D24="","",BP!D24) -> T480BRX | C11: CHARIOT-REMORQUE 2: | D11: =IF(BP!E24="","",BP!E24) -> T414EMV
A12: CONDUCTEUR: | B12: =IF(BP!G24="","",BP!G24) -> ALEX PETER | C12: PASSPORT: | D12: =IF(BP!H24="","",BP!H24) -> AB02100906
A13: LIEU DE CHARGEMENT : L’ USINE DE LUILU
A14: TRANSPORTEUR: | B14: =IF(BP!I24="","",BP!I24) -> C.STEINWEG BRIDGE (PTY) LTD
A15: TRANSIT: | B15: /
A16: BORDER: | B16: =IF(BP!J24="","",BP!J24) -> Dar es Salaam
A17: AGENT: | B17: =BP!K7 -> CONNEX
A18: NO. | B18: BAG NO. | C18: NET WEIGHT(KG) | D18: SEAL NO.
A19: 1 | B19: LU-CC26090600539 | C19: 1349 | D19: DC19939
A20: 2 | B20: LU-CC26090600528 | C20: 1618 | D20: DC15328
A21: 3 | B21: LU-CC26090600527 | C21: 1494 | D21: DC15327
A22: 4 | B22: LU-CC26090600533 | C22: 1365 | D22: DC15333
A23: 5 | B23: LU-CC26090600529 | C23: 1482 | D23: DC15329
A24: 6 | B24: LU-CC26090600535 | C24: 1343 | D24: DC15335
A25: 7 | B25: LU-CC26090600537 | C25: 1387 | D25: DC15337
A26: 8 | B26: LU-CC26090600553 | C26: 1564 | D26: DC19953
A27: 9 | B27: LU-CC26090600536 | C27: 1512 | D27: DC15336
A28: 10 | B28: LU-CC26090600549 | C28: 1242 | D28: DC19949
A29: 11 | B29: LU-CC26090600544 | C29: 1340 | D29: DC19944
A30: 12 | B30: LU-CC26090600545 | C30: 1334 | D30: DC19945
... A42: 24 | B42: LU-CC26090600590 | C42: 1400 | D42: DC19990
A44: TOTAL： | C44: =SUM(C19:C42) -> 33594
A47: BENEFICIARY
A48: LUILU RESSOURCES SAS
A49: Conseil chaleureux : veuillez vérifier le numéro/poids/lots/pièces du camion avant de signer
A50: DRIVER: | C50: SUPPLY:
A51: TRANSPORT AGENT: | C51: SECURITY:

Sheet 14装
A1: LUILU RESSOURCES SAS 鲁依鲁资源简易股份有限公司
A3: 167 AV.BUKAMA Q.MUTOSHI | D3: Tel:+243843613879
A4: C/MANIKA, KOLWEZI | D4: E-mail:xieboyang@hkexcellen.com
A5: Province du Lualaba, Democratic Republic of Congo
A6: LISTE DE COLISAGE
A7: DESCRIPTION: | B7: CONCENTRÉ DE CUIVRE | C7: N° DE LISTE DE COLISAGE : | D7: =BP!B25 -> EX202609-0519
A8: DATE: | B8: =BP!M41 -> 46276
A9: DÉTAILS DU CAMION
A10: CHEVAL: | B10: =IF(BP!C25="","",BP!C25) -> T265ECC
A11: CHARIOT-REMORQUE 1 : | B11: =IF(BP!D25="","",BP!D25) -> T983EBY | C11: CHARIOT-REMORQUE 2: | D11: =IF(BP!E25="","",BP!E25) -> T713EGF
A12: CONDUCTEUR: | B12: =IF(BP!G25="","",BP!G25) -> JAPHET FIKENI KITUMA | C12: PASSPORT: | D12: =IF(BP!H25="","",BP!H25) -> TAE679080
A13: LIEU DE CHARGEMENT : L’ USINE DE LUILU
A14: TRANSPORTEUR: | B14: =IF(BP!I25="","",BP!I25) -> C.STEINWEG BRIDGE (PTY) LTD
A15: TRANSIT: | B15: /
A16: BORDER: | B16: =IF(BP!J25="","",BP!J25) -> Dar es Salaam
A17: AGENT: | B17: =BP!K7 -> CONNEX
A18: NO. | B18: BAG NO. | C18: NET WEIGHT(KG) | D18: SEAL NO.
A19: 1 | B19: LU-CC26090600513 | C19: 1237 | D19: DC15313
A20: 2 | B20: LU-CC26090600524 | C20: 1559 | D20: DC15324
A21: 3 | B21: LU-CC26090600521 | C21: 1492 | D21: DC15321
A22: 4 | B22: LU-CC26090600522 | C22: 1492 | D22: DC15322
A23: 5 | B23: LU-CC26090600534 | C23: 1500 | D23: DC15334
A24: 6 | B24: LU-CC26090600511 | C24: 1195 | D24: DC15311
A25: 7 | B25: LU-CC26090600531 | C25: 1216 | D25: DC15331
A26: 8 | B26: LU-CC26090600541 | C26: 1323 | D26: DC19941
A27: 9 | B27: LU-CC26090600540 | C27: 1535 | D27: DC19940
A28: 10 | B28: LU-CC26090600518 | C28: 1337 | D28: DC15318
A29: 11 | B29: LU-CC26090600542 | C29: 1255 | D29: DC19942
A30: 12 | B30: LU-CC26090600552 | C30: 1281 | D30: DC19952
... A43: 25 | B43: LU-CC26090600577 | C43: 1415 | D43: DC19977
A45: TOTAL： | C45: =SUM(C19:C43) -> 33864
A48: BENEFICIARY
A49: LUILU RESSOURCES SAS
A50: Conseil chaleureux : veuillez vérifier le numéro/poids/lots/pièces du camion avant de signer
A51: DRIVER: | C51: SUPPLY:
A52: TRANSPORT AGENT: | C52: SECURITY:

Sheet 15装
A1: LUILU RESSOURCES SAS 鲁依鲁资源简易股份有限公司
A3: 167 AV.BUKAMA Q.MUTOSHI | D3: Tel:+243843613879
A4: C/MANIKA, KOLWEZI | D4: E-mail:xieboyang@hkexcellen.com
A5: Province du Lualaba, Democratic Republic of Congo
A6: LISTE DE COLISAGE
A7: DESCRIPTION: | B7: CONCENTRÉ DE CUIVRE | C7: N° DE LISTE DE COLISAGE : | D7: =BP!B26 -> EX202609-0520
A8: DATE: | B8: =BP!M41 -> 46276
A9: DÉTAILS DU CAMION
A10: CHEVAL: | B10: =IF(BP!C26="","",BP!C26) -> T485EAL
A11: CHARIOT-REMORQUE 1 : | B11: =IF(BP!D26="","",BP!D26) -> T331DEN | C11: CHARIOT-REMORQUE 2: | D11: =IF(BP!E26="","",BP!E26) -> T710EGF
A12: CONDUCTEUR: | B12: =IF(BP!G26="","",BP!G26) -> EDIGA YORAM | C12: PASSPORT: | D12: =IF(BP!H26="","",BP!H26) -> AB02093890
A13: LIEU DE CHARGEMENT : L’ USINE DE LUILU
A14: TRANSPORTEUR: | B14: =IF(BP!I26="","",BP!I26) -> C.STEINWEG BRIDGE (PTY) LTD
A15: TRANSIT: | B15: /
A16: BORDER: | B16: =IF(BP!J26="","",BP!J26) -> Dar es Salaam
A17: AGENT: | B17: =BP!K7 -> CONNEX
A18: NO. | B18: BAG NO. | C18: NET WEIGHT(KG) | D18: SEAL NO.
A19: 1 | B19: LU-CC26090600573 | C19: 1410 | D19: DC19973
A20: 2 | B20: LU-CC26090600571 | C20: 1408 | D20: DC19971
A21: 3 | B21: LU-CC26090600581 | C21: 1427 | D21: DC19981
A22: 4 | B22: LU-CC26090600575 | C22: 1613 | D22: DC19975
A23: 5 | B23: LU-CC26090600565 | C23: 1451 | D23: DC19965
A24: 6 | B24: LU-CC26090600567 | C24: 1457 | D24: DC19967
A25: 7 | B25: LU-CC26090600576 | C25: 1527 | D25: DC19976
A26: 8 | B26: LU-CC26090600578 | C26: 1387 | D26: DC19978
A27: 9 | B27: LU-CC26090600592 | C27: 1518 | D27: DC19992
A28: 10 | B28: LU-CC26090600588 | C28: 1480 | D28: DC19988
A29: 11 | B29: LU-CC26090600589 | C29: 1381 | D29: DC19989
A30: 12 | B30: LU-CC26090600587 | C30: 1463 | D30: DC19987
... A41: 23 | B41: LU-CC26090700619 | C41: 1408 | D41: DC19919
A43: TOTAL： | C43: =SUM(C19:C41) -> 33824
A46: BENEFICIARY
A47: LUILU RESSOURCES SAS
A48: Conseil chaleureux : veuillez vérifier le numéro/poids/lots/pièces du camion avant de signer
A49: DRIVER: | C49: SUPPLY:
A50: TRANSPORT AGENT: | C50: SECURITY:

Sheet 16装
A1: LUILU RESSOURCES SAS 鲁依鲁资源简易股份有限公司
A3: 167 AV.BUKAMA Q.MUTOSHI | D3: Tel:+243843613879
A4: C/MANIKA, KOLWEZI | D4: E-mail:xieboyang@hkexcellen.com
A5: Province du Lualaba, Democratic Republic of Congo
A6: LISTE DE COLISAGE
A7: DESCRIPTION: | B7: CONCENTRÉ DE CUIVRE | C7: N° DE LISTE DE COLISAGE : | D7: =BP!B27 -> EX202609-0521
A8: DATE: | B8: =BP!M41 -> 46276
A9: DÉTAILS DU CAMION
A10: CHEVAL: | B10: =IF(BP!C27="","",BP!C27) -> T177EBK
A11: CHARIOT-REMORQUE 1 : | B11: =IF(BP!D27="","",BP!D27) -> T796BMY | C11: CHARIOT-REMORQUE 2: | D11: =IF(BP!E27="","",BP!E27) -> T973EHX
A12: CONDUCTEUR: | B12: =IF(BP!G27="","",BP!G27) -> ISSA MANYANGA | C12: PASSPORT: | D12: =IF(BP!H27="","",BP!H27) -> TAE842876
A13: LIEU DE CHARGEMENT : L’ USINE DE LUILU
A14: TRANSPORTEUR: | B14: =IF(BP!I27="","",BP!I27) -> C.STEINWEG BRIDGE (PTY) LTD
A15: TRANSIT: | B15: /
A16: BORDER: | B16: =IF(BP!J27="","",BP!J27) -> Dar es Salaam
A17: AGENT: | B17: =BP!K7 -> CONNEX
A18: NO. | B18: BAG NO. | C18: NET WEIGHT(KG) | D18: SEAL NO.
A19: 1 | B19: LU-CC26090700610 | C19: 1398 | D19: DC19910
A20: 2 | B20: LU-CC26090700618 | C20: 1432 | D20: DC19918
A21: 3 | B21: LU-CC26090600605 | C21: 1268 | D21: DC19905
A22: 4 | B22: LU-CC26090700628 | C22: 1235 | D22: DC19928
A23: 5 | B23: LU-CC26090600606 | C23: 1363 | D23: DC19906
A24: 6 | B24: LU-CC26090600596 | C24: 1372 | D24: DC19996
A25: 7 | B25: LU-CC26090700625 | C25: 1502 | D25: DC19925
A26: 8 | B26: LU-CC26090600597 | C26: 1323 | D26: DC19997
A27: 9 | B27: LU-CC26090700607 | C27: 1680 | D27: DC19907
A28: 10 | B28: LU-CC26090600595 | C28: 1297 | D28: DC19995
A29: 11 | B29: LU-CC26090700621 | C29: 1541 | D29: DC19921
A30: 12 | B30: LU-CC26090700614 | C30: 1511 | D30: DC19914
... A42: 24 | B42: LU-CC26090500423 | C42: 1367 | D42: DC01723
A44: TOTAL： | C44: =SUM(C19:C42) -> 34002
A47: BENEFICIARY
A48: LUILU RESSOURCES SAS
A49: Conseil chaleureux : veuillez vérifier le numéro/poids/lots/pièces du camion avant de signer
A50: DRIVER: | C50: SUPPLY:
A51: TRANSPORT AGENT: | C51: SECURITY:

Sheet 17装
A1: LUILU RESSOURCES SAS 鲁依鲁资源简易股份有限公司
A3: 167 AV.BUKAMA Q.MUTOSHI | D3: Tel:+243843613879
A4: C/MANIKA, KOLWEZI | D4: E-mail:xieboyang@hkexcellen.com
A5: Province du Lualaba, Democratic Republic of Congo
A6: LISTE DE COLISAGE
A7: DESCRIPTION: | B7: CONCENTRÉ DE CUIVRE | C7: N° DE LISTE DE COLISAGE : | D7: =BP!B28 -> EX202609-0522
A8: DATE: | B8: =BP!M41 -> 46276
A9: DÉTAILS DU CAMION
A10: CHEVAL: | B10: =IF(BP!C28="","",BP!C28) -> T952DUM
A11: CHARIOT-REMORQUE 1 : | B11: =IF(BP!D28="","",BP!D28) -> T919ASZ | C11: CHARIOT-REMORQUE 2: | D11: =IF(BP!E28="","",BP!E28) -> NA
A12: CONDUCTEUR: | B12: =IF(BP!G28="","",BP!G28) -> MIKA KISUNGWE | C12: PASSPORT: | D12: =IF(BP!H28="","",BP!H28) -> TAE650086
A13: LIEU DE CHARGEMENT : L’ USINE DE LUILU
A14: TRANSPORTEUR: | B14: =IF(BP!I28="","",BP!I28) -> C.STEINWEG BRIDGE (PTY) LTD
A15: TRANSIT: | B15: /
A16: BORDER: | B16: =IF(BP!J28="","",BP!J28) -> Dar es Salaam
A17: AGENT: | B17: =BP!K7 -> CONNEX
A18: NO. | B18: BAG NO. | C18: NET WEIGHT(KG) | D18: SEAL NO.
A19: 1 | B19: LU-CC260806167 | C19: 1417 | D19: 109467
A20: 2 | B20: LU-CC26080703 | C20: 1411 | D20: 109503
A21: 3 | B21: LU-CC25121162 | C21: 1242 | D21: 103950
A22: 4 | B22: LU-CC26080712 | C22: 1336 | D22: 109512
A23: 5 | B23: LU-CC26072014 | C23: 1482 | D23: 114214
A24: 6 | B24: LU-CC260728138 | C24: 1618 | D24: 113738
A25: 7 | B25: LU-CC25122431 | C25: 1052 | D25: 111019
A26: 8 | B26: LU-CC26072036 | C26: 1069 | D26: 114236
A27: 9 | B27: LU-CC26071934 | C27: 1320 | D27: 114034
A28: 10 | B28: LU-CC260108101 | C28: 1449 | D28: 111881
A29: 11 | B29: LU-CC251120212 | C29: 1168 | D29: 115422
A30: 12 | B30: LU-CC26011115 | C30: 1187 | D30: 111945
... A40: 22 | B40: LU-CC260727135 | C40: 1276 | D40: 113535
A42: TOTAL： | C42: =SUM(C19:C40) -> 29584
A45: BENEFICIARY
A46: LUILU RESSOURCES SAS
A47: Conseil chaleureux : veuillez vérifier le numéro/poids/lots/pièces du camion avant de signer
A48: DRIVER: | C48: SUPPLY:
A49: TRANSPORT AGENT: | C49: SECURITY:

Sheet 18装
A1: LUILU RESSOURCES SAS 鲁依鲁资源简易股份有限公司
A3: 167 AV.BUKAMA Q.MUTOSHI | D3: Tel:+243843613879
A4: C/MANIKA, KOLWEZI | D4: E-mail:xieboyang@hkexcellen.com
A5: Province du Lualaba, Democratic Republic of Congo
A6: LISTE DE COLISAGE
A7: DESCRIPTION: | B7: CONCENTRÉ DE CUIVRE | C7: N° DE LISTE DE COLISAGE : | D7: =BP!B29 -> EX202609-0523
A8: DATE: | B8: =BP!M41 -> 46276
A9: DÉTAILS DU CAMION
A10: CHEVAL: | B10: =IF(BP!C29="","",BP!C29) -> T502DMJ
A11: CHARIOT-REMORQUE 1 : | B11: =IF(BP!D29="","",BP!D29) -> T440CFG | C11: CHARIOT-REMORQUE 2: | D11: =IF(BP!E29="","",BP!E29) -> T364ELY
A12: CONDUCTEUR: | B12: =IF(BP!G29="","",BP!G29) -> SHARIFU JUMANNE | C12: PASSPORT: | D12: =IF(BP!H29="","",BP!H29) -> TAE869967
A13: LIEU DE CHARGEMENT : L’ USINE DE LUILU
A14: TRANSPORTEUR: | B14: =IF(BP!I29="","",BP!I29) -> C.STEINWEG BRIDGE (PTY) LTD
A15: TRANSIT: | B15: /
A16: BORDER: | B16: =IF(BP!J29="","",BP!J29) -> Dar es Salaam
A17: AGENT: | B17: =BP!K7 -> CONNEX
A18: NO. | B18: BAG NO. | C18: NET WEIGHT(KG) | D18: SEAL NO.
A19: 1 | B19: LU-CC26090300039 | C19: 1567 | D19: DC14439
A20: 2 | B20: LU-CC26090300040 | C20: 1484 | D20: DC14440
A21: 3 | B21: LU-CC26090300113 | C21: 1325 | D21: DC14413
A22: 4 | B22: LU-CC26090300043 | C22: 1512 | D22: DC14443
A23: 5 | B23: LU-CC26090300044 | C23: 1589 | D23: DC02064
A24: 6 | B24: LU-CC26090200031 | C24: 1529 | D24: DC02081
A25: 7 | B25: LU-CC26090600458 | C25: 1531 | D25: DC15358
A26: 8 | B26: LU-CC26090700724 | C26: 1535 | D26: DC01424
A27: 9 | B27: LU-CC26090300114 | C27: 1412 | D27: DC14414
A28: 10 | B28: LU-CC26090700748 | C28: 1357 | D28: DC01448
A29: 11 | B29: LU-CC26090300116 | C29: 1460 | D29: DC14416
A30: 12 | B30: LU-CC26090700716 | C30: 1452 | D30: DC01416
... A41: 23 | B41: LU-CC26090700692 | C41: 1473 | D41: DC14992
A43: TOTAL： | C43: =SUM(C19:C41) -> 33661
A46: BENEFICIARY
A47: LUILU RESSOURCES SAS
A48: Conseil chaleureux : veuillez vérifier le numéro/poids/lots/pièces du camion avant de signer
A49: DRIVER: | C49: SUPPLY:
A50: TRANSPORT AGENT: | C50: SECURITY:

Sheet 19装
A1: LUILU RESSOURCES SAS 鲁依鲁资源简易股份有限公司
A3: 167 AV.BUKAMA Q.MUTOSHI | D3: Tel:+243843613879
A4: C/MANIKA, KOLWEZI | D4: E-mail:xieboyang@hkexcellen.com
A5: Province du Lualaba, Democratic Republic of Congo
A6: LISTE DE COLISAGE
A7: DESCRIPTION: | B7: CONCENTRÉ DE CUIVRE | C7: N° DE LISTE DE COLISAGE : | D7: =BP!B30 -> EX202609-0524
A8: DATE: | B8: =BP!M41 -> 46276
A9: DÉTAILS DU CAMION
A10: CHEVAL: | B10: =IF(BP!C30="","",BP!C30) -> T540ECN
A11: CHARIOT-REMORQUE 1 : | B11: =IF(BP!D30="","",BP!D30) -> T827ENG | C11: CHARIOT-REMORQUE 2: | D11: =IF(BP!E30="","",BP!E30) -> NA
A12: CONDUCTEUR: | B12: =IF(BP!G30="","",BP!G30) -> MUSTAFER AMIR | C12: PASSPORT: | D12: =IF(BP!H30="","",BP!H30) -> AB02106113
A13: LIEU DE CHARGEMENT : L’ USINE DE LUILU
A14: TRANSPORTEUR: | B14: =IF(BP!I30="","",BP!I30) -> IMPERIAL ROAD HAULAGE LTD
A15: TRANSIT: | B15: /
A16: BORDER: | B16: =IF(BP!J30="","",BP!J30) -> Dar es Salaam
A17: AGENT: | B17: =BP!K7 -> CONNEX
A18: NO. | B18: BAG NO. | C18: NET WEIGHT(KG) | D18: SEAL NO.
A19: 1 | B19: LU-CC26090300118 | C19: 1379 | D19: DC14418
A20: 2 | B20: LU-CC26090700725 | C20: 1449 | D20: DC01425
A21: 3 | B21: LU-CC26090700699 | C21: 1390 | D21: DC14999
A22: 4 | B22: LU-CC26090300115 | C22: 1468 | D22: DC14415
A23: 5 | B23: LU-CC26090500223 | C23: 1402 | D23: DC01923
A24: 6 | B24: LU-CC26090700946 | C24: 1399 | D24: DC14646
A25: 7 | B25: LU-CC26090700713 | C25: 1479 | D25: DC01413
A26: 8 | B26: LU-CC26090700717 | C26: 1391 | D26: DC01417
A27: 9 | B27: LU-CC26090700753 | C27: 1301 | D27: DC01453
A28: 10 | B28: LU-CC26090600469 | C28: 1366 | D28: DC15369
A29: 11 | B29: LU-CC26090600508 | C29: 1582 | D29: DC15308
A30: 12 | B30: LU-CC26090700729 | C30: 1463 | D30: DC01429
... A41: 23 | B41: LU-CC26090200024 | C41: 1321 | D41: DC02074
A43: TOTAL： | C43: =SUM(C19:C41) -> 32479
A46: BENEFICIARY
A47: LUILU RESSOURCES SAS
A48: Conseil chaleureux : veuillez vérifier le numéro/poids/lots/pièces du camion avant de signer
A49: DRIVER: | C49: SUPPLY:
A50: TRANSPORT AGENT: | C50: SECURITY:

Sheet 20装
A1: LUILU RESSOURCES SAS 鲁依鲁资源简易股份有限公司
A3: 167 AV.BUKAMA Q.MUTOSHI | D3: Tel:+243843613879
A4: C/MANIKA, KOLWEZI | D4: E-mail:xieboyang@hkexcellen.com
A5: Province du Lualaba, Democratic Republic of Congo
A6: LISTE DE COLISAGE
A7: DESCRIPTION: | B7: CONCENTRÉ DE CUIVRE | C7: N° DE LISTE DE COLISAGE : | D7: =BP!B31 -> EX202609-0525
A8: DATE: | B8: =BP!M41 -> 46276
A9: DÉTAILS DU CAMION
A10: CHEVAL: | B10: =IF(BP!C31="","",BP!C31) -> T699DRY
A11: CHARIOT-REMORQUE 1 : | B11: =IF(BP!D31="","",BP!D31) -> T699DRY | C11: CHARIOT-REMORQUE 2: | D11: =IF(BP!E31="","",BP!E31) -> T207DSK
A12: CONDUCTEUR: | B12: =IF(BP!G31="","",BP!G31) -> CHARLES LUCAS MTENGULE | C12: PASSPORT: | D12: =IF(BP!H31="","",BP!H31) -> TAE690209
A13: LIEU DE CHARGEMENT : L’ USINE DE LUILU
A14: TRANSPORTEUR: | B14: =IF(BP!I31="","",BP!I31) -> OVERLAND INTERNATIONAL AG
A15: TRANSIT: | B15: /
A16: BORDER: | B16: =IF(BP!J31="","",BP!J31) -> Dar es Salaam
A17: AGENT: | B17: =BP!K7 -> CONNEX
A18: NO. | B18: BAG NO. | C18: NET WEIGHT(KG) | D18: SEAL NO.
A19: 1 | B19: LU-CC26090700703 | C19: 1406 | D19: DC01403
A20: 2 | B20: LU-CC26090700727 | C20: 1421 | D20: DC01427
A21: 3 | B21: LU-CC26090600488 | C21: 1392 | D21: DC15388
A22: 4 | B22: LU-CC26090700715 | C22: 1357 | D22: DC01415
A23: 5 | B23: LU-CC26090500302 | C23: 1375 | D23: DC15002
A24: 6 | B24: LU-CC26090700738 | C24: 1441 | D24: DC01438
A25: 7 | B25: LU-CC26090600479 | C25: 1607 | D25: DC15379
A26: 8 | B26: LU-CC26090700755 | C26: 1364 | D26: DC01455
A27: 9 | B27: LU-CC26090700739 | C27: 1453 | D27: DC01439
A28: 10 | B28: LU-CC26090600497 | C28: 1441 | D28: DC15397
A29: 11 | B29: LU-CC26090700750 | C29: 1412 | D29: DC01450
A30: 12 | B30: LU-CC26090700732 | C30: 1356 | D30: DC01432
... A42: 24 | B42: LU-CC26090500403 | C42: 1379 | D42: DC01703
A44: TOTAL： | C44: =SUM(C19:C42) -> 33682
A47: BENEFICIARY
A48: LUILU RESSOURCES SAS
A49: Conseil chaleureux : veuillez vérifier le numéro/poids/lots/pièces du camion avant de signer
A50: DRIVER: | C50: SUPPLY:
A51: TRANSPORT AGENT: | C51: SECURITY:

Sheet 21装
A1: LUILU RESSOURCES SAS 鲁依鲁资源简易股份有限公司
A3: 167 AV.BUKAMA Q.MUTOSHI | D3: Tel:+243843613879
A4: C/MANIKA, KOLWEZI | D4: E-mail:xieboyang@hkexcellen.com
A5: Province du Lualaba, Democratic Republic of Congo
A6: LISTE DE COLISAGE
A7: DESCRIPTION: | B7: CONCENTRÉ DE CUIVRE | C7: N° DE LISTE DE COLISAGE : | D7: =BP!B32 -> EX202609-0526
A8: DATE: | B8: =BP!M41 -> 46276
A9: DÉTAILS DU CAMION
A10: CHEVAL: | B10: =IF(BP!C32="","",BP!C32) -> T341EPL
A11: CHARIOT-REMORQUE 1 : | B11: =IF(BP!D32="","",BP!D32) -> T731EPJ | C11: CHARIOT-REMORQUE 2: | D11: =IF(BP!E32="","",BP!E32) -> NA
A12: CONDUCTEUR: | B12: =IF(BP!G32="","",BP!G32) -> SALEHE HEMEDI | C12: PASSPORT: | D12: =IF(BP!H32="","",BP!H32) -> TAE791546
A13: LIEU DE CHARGEMENT : L’ USINE DE LUILU
A14: TRANSPORTEUR: | B14: =IF(BP!I32="","",BP!I32) -> VAN MO COMPANY LIMITED
A15: TRANSIT: | B15: /
A16: BORDER: | B16: =IF(BP!J32="","",BP!J32) -> Dar es Salaam
A17: AGENT: | B17: =BP!K7 -> CONNEX
A18: NO. | B18: BAG NO. | C18: NET WEIGHT(KG) | D18: SEAL NO.
A19: 1 | B19: LU-CC26090500266 | C19: 1387 | D19: DC15066
A20: 2 | B20: LU-CC26090500277 | C20: 1345 | D20: DC15077
A21: 3 | B21: LU-CC26090500232 | C21: 1313 | D21: DC01932
A22: 4 | B22: LU-CC26090500255 | C22: 1368 | D22: DC15055
A23: 5 | B23: LU-CC26090500233 | C23: 1391 | D23: DC01933
A24: 6 | B24: LU-CC26090500322 | C24: 1342 | D24: DC15022
A25: 7 | B25: LU-CC26090500299 | C25: 1351 | D25: DC15099
A26: 8 | B26: LU-CC26090400198 | C26: 1349 | D26: DC01998
A27: 9 | B27: LU-CC26090500268 | C27: 1402 | D27: DC15068
A28: 10 | B28: LU-CC26090500244 | C28: 1337 | D28: DC15044
A29: 11 | B29: LU-CC26090500222 | C29: 1487 | D29: DC01922
A30: 12 | B30: LU-CC26090500234 | C30: 1541 | D30: DC01934
... A40: 22 | B40: LU-CC26090600436 | C40: 1333 | D40: DC01736
A42: TOTAL： | C42: =SUM(C19:C40) -> 30584
A45: BENEFICIARY
A46: LUILU RESSOURCES SAS
A47: Conseil chaleureux : veuillez vérifier le numéro/poids/lots/pièces du camion avant de signer
A48: DRIVER: | C48: SUPPLY:
A49: TRANSPORT AGENT: | C49: SECURITY:

Sheet 22装
A1: LUILU RESSOURCES SAS 鲁依鲁资源简易股份有限公司
A3: 167 AV.BUKAMA Q.MUTOSHI | D3: Tel:+243843613879
A4: C/MANIKA, KOLWEZI | D4: E-mail:xieboyang@hkexcellen.com
A5: Province du Lualaba, Democratic Republic of Congo
A6: LISTE DE COLISAGE
A7: DESCRIPTION: | B7: CONCENTRÉ DE CUIVRE | C7: N° DE LISTE DE COLISAGE : | D7: =BP!B33 -> EX202609-0527
A8: DATE: | B8: =BP!M41 -> 46276
A9: DÉTAILS DU CAMION
A10: CHEVAL: | B10: =IF(BP!C33="","",BP!C33) -> T626ECB
A11: CHARIOT-REMORQUE 1 : | B11: =IF(BP!D33="","",BP!D33) -> T557BBE | C11: CHARIOT-REMORQUE 2: | D11: =IF(BP!E33="","",BP!E33) -> T236DTC
A12: CONDUCTEUR: | B12: =IF(BP!G33="","",BP!G33) -> SALUM MUMBA | C12: PASSPORT: | D12: =IF(BP!H33="","",BP!H33) -> TAE527007
A13: LIEU DE CHARGEMENT : L’ USINE DE LUILU
A14: TRANSPORTEUR: | B14: =IF(BP!I33="","",BP!I33) -> C.STEINWEG BRIDGE (PTY) LTD
A15: TRANSIT: | B15: /
A16: BORDER: | B16: =IF(BP!J33="","",BP!J33) -> Dar es Salaam
A17: AGENT: | B17: =BP!K7 -> CONNEX
A18: NO. | B18: BAG NO. | C18: NET WEIGHT(KG) | D18: SEAL NO.
A19: 1 | B19: LU-CC26090600496 | C19: 1513 | D19: DC15396
A20: 2 | B20: LU-CC26090600484 | C20: 1597 | D20: DC15384
A21: 3 | B21: LU-CC26090600474 | C21: 1366 | D21: DC15374
A22: 4 | B22: LU-CC26090600441 | C22: 1288 | D22: DC15341
A23: 5 | B23: LU-CC26090500413 | C23: 1366 | D23: DC01713
A24: 6 | B24: LU-CC26090600439 | C24: 1342 | D24: DC15339
A25: 7 | B25: LU-CC26090600442 | C25: 1378 | D25: DC15342
A26: 8 | B26: LU-CC26090600461 | C26: 1402 | D26: DC15361
A27: 9 | B27: LU-CC26090600446 | C27: 1254 | D27: DC15346
A28: 10 | B28: LU-CC26090600438 | C28: 1232 | D28: DC01738
A29: 11 | B29: LU-CC26090500414 | C29: 1326 | D29: DC01714
A30: 12 | B30: LU-CC26090600443 | C30: 1220 | D30: DC15343
... A43: 25 | B43: LU-CC26090600486 | C43: 1243 | D43: DC15386
A45: TOTAL： | C45: =SUM(C19:C43) -> 33752
A48: BENEFICIARY
A49: LUILU RESSOURCES SAS
A50: Conseil chaleureux : veuillez vérifier le numéro/poids/lots/pièces du camion avant de signer
A51: DRIVER: | C51: SUPPLY:
A52: TRANSPORT AGENT: | C52: SECURITY:

Sheet 23装
A1: LUILU RESSOURCES SAS 鲁依鲁资源简易股份有限公司
A3: 167 AV.BUKAMA Q.MUTOSHI | D3: Tel:+243843613879
A4: C/MANIKA, KOLWEZI | D4: E-mail:xieboyang@hkexcellen.com
A5: Province du Lualaba, Democratic Republic of Congo
A6: LISTE DE COLISAGE
A7: DESCRIPTION: | B7: CONCENTRÉ DE CUIVRE | C7: N° DE LISTE DE COLISAGE : | D7: =BP!B34 -> EX202609-0528
A8: DATE: | B8: =BP!M41 -> 46276
A9: DÉTAILS DU CAMION
A10: CHEVAL: | B10: =IF(BP!C34="","",BP!C34) -> T222DFL
A11: CHARIOT-REMORQUE 1 : | B11: =IF(BP!D34="","",BP!D34) -> T596CBD | C11: CHARIOT-REMORQUE 2: | D11: =IF(BP!E34="","",BP!E34) -> T429EMV
A12: CONDUCTEUR: | B12: =IF(BP!G34="","",BP!G34) -> MUSTAFA OMARY | C12: PASSPORT: | D12: =IF(BP!H34="","",BP!H34) -> AB02103761
A13: LIEU DE CHARGEMENT : L’ USINE DE LUILU
A14: TRANSPORTEUR: | B14: =IF(BP!I34="","",BP!I34) -> C.STEINWEG BRIDGE (PTY) LTD
A15: TRANSIT: | B15: /
A16: BORDER: | B16: =IF(BP!J34="","",BP!J34) -> Dar es Salaam
A17: AGENT: | B17: =BP!K7 -> CONNEX
A18: NO. | B18: BAG NO. | C18: NET WEIGHT(KG) | D18: SEAL NO.
A19: 1 | B19: LU-CC26090600481 | C19: 1587 | D19: DC15381
A20: 2 | B20: LU-CC26090200019 | C20: 1598 | D20: DC02029
A21: 3 | B21: LU-CC26090200025 | C21: 1452 | D21: DC02075
A22: 4 | B22: LU-CC26090200016 | C22: 1411 | D22: DC02036
A23: 5 | B23: LU-CC26090200018 | C23: 1518 | D23: DC02028
A24: 6 | B24: LU-CC26090200005 | C24: 1459 | D24: DC02041
A25: 7 | B25: LU-CC26090700691 | C25: 1441 | D25: DC02100
A26: 8 | B26: LU-CC26090600482 | C26: 1553 | D26: DC15382
A27: 9 | B27: LU-CC26090600503 | C27: 1437 | D27: DC15303
A28: 10 | B28: LU-CC26090700693 | C28: 1451 | D28: DC14993
A29: 11 | B29: LU-CC26090600472 | C29: 1530 | D29: DC15372
A30: 12 | B30: LU-CC26090700705 | C30: 1393 | D30: DC01405
... A42: 24 | B42: LU-CC26090600450 | C42: 1350 | D42: DC15350
A44: TOTAL： | C44: =SUM(C19:C42) -> 34690
A47: BENEFICIARY
A48: LUILU RESSOURCES SAS
A49: Conseil chaleureux : veuillez vérifier le numéro/poids/lots/pièces du camion avant de signer
A50: DRIVER: | C50: SUPPLY:
A51: TRANSPORT AGENT: | C51: SECURITY:

Sheet 24装
A1: LUILU RESSOURCES SAS 鲁依鲁资源简易股份有限公司
A3: 167 AV.BUKAMA Q.MUTOSHI | D3: Tel:+243843613879
A4: C/MANIKA, KOLWEZI | D4: E-mail:xieboyang@hkexcellen.com
A5: Province du Lualaba, Democratic Republic of Congo
A6: LISTE DE COLISAGE
A7: DESCRIPTION: | B7: CONCENTRÉ DE CUIVRE | C7: N° DE LISTE DE COLISAGE : | D7: =BP!B35 -> EX202609-0529
A8: DATE: | B8: =BP!M41 -> 46276
A9: DÉTAILS DU CAMION
A10: CHEVAL: | B10: =IF(BP!C35="","",BP!C35) -> T602DYY
A11: CHARIOT-REMORQUE 1 : | B11: =IF(BP!D35="","",BP!D35) -> T494BRX | C11: CHARIOT-REMORQUE 2: | D11: =IF(BP!E35="","",BP!E35) -> T415EPH
A12: CONDUCTEUR: | B12: =IF(BP!G35="","",BP!G35) -> IDDI JUMA | C12: PASSPORT: | D12: =IF(BP!H35="","",BP!H35) -> TAE854999
A13: LIEU DE CHARGEMENT : L’ USINE DE LUILU
A14: TRANSPORTEUR: | B14: =IF(BP!I35="","",BP!I35) -> C.STEINWEG BRIDGE (PTY) LTD
A15: TRANSIT: | B15: /
A16: BORDER: | B16: =IF(BP!J35="","",BP!J35) -> Dar es Salaam
A17: AGENT: | B17: =BP!K7 -> CONNEX
A18: NO. | B18: BAG NO. | C18: NET WEIGHT(KG) | D18: SEAL NO.
A19: 1 | B19: LU-CC26090700938 | C19: 1507 | D19: DC14638
A20: 2 | B20: LU-CC26090700944 | C20: 1517 | D20: DC14644
A21: 3 | B21: LU-CC26090700939 | C21: 1566 | D21: DC14639
A22: 4 | B22: LU-CC26090200032 | C22: 1589 | D22: DC02042
A23: 5 | B23: LU-CC26090700937 | C23: 1533 | D23: DC14637
A24: 6 | B24: LU-CC26090700941 | C24: 1625 | D24: DC14641
A25: 7 | B25: LU-CC26090700945 | C25: 1571 | D25: DC14645
A26: 8 | B26: LU-CC26090200036 | C26: 1516 | D26: DC02066
A27: 9 | B27: LU-CC26090600492 | C27: 1666 | D27: DC15392
A28: 10 | B28: LU-CC26090600480 | C28: 1600 | D28: DC15380
A29: 11 | B29: LU-CC26090600470 | C29: 1142 | D29: DC15370
A30: 12 | B30: LU-CC26090200035 | C30: 1541 | D30: DC02085
... A41: 23 | B41: LU-CC26090300093 | C41: 1533 | D41: DC14493
A43: TOTAL： | C43: =SUM(C19:C41) -> 34270
A46: BENEFICIARY
A47: LUILU RESSOURCES SAS
A48: Conseil chaleureux : veuillez vérifier le numéro/poids/lots/pièces du camion avant de signer
A49: DRIVER: | C49: SUPPLY:
A50: TRANSPORT AGENT: | C50: SECURITY:

Sheet 25装
A1: LUILU RESSOURCES SAS 鲁依鲁资源简易股份有限公司
A3: 167 AV.BUKAMA Q.MUTOSHI | D3: Tel:+243843613879
A4: C/MANIKA, KOLWEZI | D4: E-mail:xieboyang@hkexcellen.com
A5: Province du Lualaba, Democratic Republic of Congo
A6: LISTE DE COLISAGE
A7: DESCRIPTION: | B7: CONCENTRÉ DE CUIVRE | C7: N° DE LISTE DE COLISAGE : | D7: =BP!B36 -> EX202609-0530
A8: DATE: | B8: =BP!M41 -> 46276
A9: DÉTAILS DU CAMION
A10: CHEVAL: | B10: =IF(BP!C36="","",BP!C36) -> T605EGH
A11: CHARIOT-REMORQUE 1 : | B11: =IF(BP!D36="","",BP!D36) -> T314ECC | C11: CHARIOT-REMORQUE 2: | D11: =IF(BP!E36="","",BP!E36) -> T980EHQ
A12: CONDUCTEUR: | B12: =IF(BP!G36="","",BP!G36) -> RAMADHAN RUME | C12: PASSPORT: | D12: =IF(BP!H36="","",BP!H36) -> TAE499949
A13: LIEU DE CHARGEMENT : L’ USINE DE LUILU
A14: TRANSPORTEUR: | B14: =IF(BP!I36="","",BP!I36) -> C.STEINWEG BRIDGE (PTY) LTD
A15: TRANSIT: | B15: /
A16: BORDER: | B16: =IF(BP!J36="","",BP!J36) -> Dar es Salaam
A17: AGENT: | B17: =BP!K7 -> CONNEX
A18: NO. | B18: BAG NO. | C18: NET WEIGHT(KG) | D18: SEAL NO.
A19: 1 | B19: LU-CC26090500342 | C19: 1391 | D19: DC01742
A20: 2 | B20: LU-CC26090200009 | C20: 1287 | D20: DC02049
A21: 3 | B21: LU-CC26090200030 | C21: 1418 | D21: DC02080
A22: 4 | B22: LU-CC26090200015 | C22: 1384 | D22: DC02025
A23: 5 | B23: LU-CC26090500404 | C23: 1415 | D23: DC01704
A24: 6 | B24: LU-CC26090500394 | C24: 1370 | D24: DC01794
A25: 7 | B25: LU-CC26090500384 | C25: 1531 | D25: DC01784
A26: 8 | B26: LU-CC26090500349 | C26: 1451 | D26: DC01749
A27: 9 | B27: LU-CC26090500345 | C27: 1320 | D27: DC01745
A28: 10 | B28: LU-CC26090500340 | C28: 1366 | D28: DC01740
A29: 11 | B29: LU-CC26090500346 | C29: 1475 | D29: DC01746
A30: 12 | B30: LU-CC26090600462 | C30: 1267 | D30: DC15362
... A43: 25 | B43: LU-CC26090500369 | C43: 1329 | D43: DC01769
A45: TOTAL： | C45: =SUM(C19:C43) -> 34652
A48: BENEFICIARY
A49: LUILU RESSOURCES SAS
A50: Conseil chaleureux : veuillez vérifier le numéro/poids/lots/pièces du camion avant de signer
A51: DRIVER: | C51: SUPPLY:
A52: TRANSPORT AGENT: | C52: SECURITY:

Sheet 26装
A1: LUILU RESSOURCES SAS 鲁依鲁资源简易股份有限公司
A3: 167 AV.BUKAMA Q.MUTOSHI | D3: Tel:+243843613879
A4: C/MANIKA, KOLWEZI | D4: E-mail:xieboyang@hkexcellen.com
A5: Province du Lualaba, Democratic Republic of Congo
A6: LISTE DE COLISAGE
A7: DESCRIPTION: | B7: CONCENTRÉ DE CUIVRE | C7: N° DE LISTE DE COLISAGE : | D7: =BP!B37 -> EX202609-0531
A8: DATE: | B8: =BP!M41 -> 46276
A9: DÉTAILS DU CAMION
A10: CHEVAL: | B10: =IF(BP!C37="","",BP!C37) -> T412EEG
A11: CHARIOT-REMORQUE 1 : | B11: =IF(BP!D37="","",BP!D37) -> T826EFK | C11: CHARIOT-REMORQUE 2: | D11: =IF(BP!E37="","",BP!E37) -> NA
A12: CONDUCTEUR: | B12: =IF(BP!G37="","",BP!G37) -> HASSAN OMAR | C12: PASSPORT: | D12: =IF(BP!H37="","",BP!H37) -> TAE180869
A13: LIEU DE CHARGEMENT : L’ USINE DE LUILU
A14: TRANSPORTEUR: | B14: =IF(BP!I37="","",BP!I37) -> IMPERIAL ROAD HAULAGE LTD
A15: TRANSIT: | B15: /
A16: BORDER: | B16: =IF(BP!J37="","",BP!J37) -> Dar es Salaam
A17: AGENT: | B17: =BP!K7 -> CONNEX
A18: NO. | B18: BAG NO. | C18: NET WEIGHT(KG) | D18: SEAL NO.
A19: 1 | B19: LU-CC26090200022 | C19: 1575 | D19: DC02072
A20: 2 | B20: LU-CC26090700718 | C20: 1459 | D20: DC01418
